[0;33m--- idf_monitor on /dev/ttyUSB0 115200 ---[0m
[0;33m--- Quit: Ctrl+] | Menu: Ctrl+T | Help: Ctrl+T followed by Ctrl+H ---[0m
Exception in thread Thread-2 (_run_outer):
Traceback (most recent call last):
  File "/home/bvsirghe/.espressif/python_env/idf5.2_py3.11_env/lib/python3.11/site-packages/serial/serialposix.py", line 322, in open
[0m
    self.fd = os.open(self.portstr, os.O_RDWR | os.O_NOCTTY | os.O_NONBLOCK)
              ^^^^^^^^^^^^^^^^^^^^^^^^^^^^^^^^^^^^^^^^^^^^^^^^^^^^^^^^^^^^^^
PermissionError: [Errno 13] Permission denied: '/dev/ttyUSB0'

During handling of the above exception, another exception occurred:

Traceback (most recent call last):
  File "/usr/lib/python3.11/threading.py", line 1038, in _bootstrap_inner
    self.run()
  File "/usr/lib/python3.11/threading.py", line 975, in run
    self._target(*self._args, **self._kwargs)
  File "/home/bvsirghe/.espressif/python_env/idf5.2_py3.11_env/lib/python3.11/site-packages/esp_idf_monitor/base/stoppable_thread.py", line 47, in _run_outer
    self.run()
  File "/home/bvsirghe/.espressif/python_env/idf5.2_py3.11_env/lib/python3.11/site-packages/esp_idf_monitor/base/serial_reader.py", line 53, in run
    self.serial.open()
  File "/home/bvsirghe/.espressif/python_env/idf5.2_py3.11_env/lib/python3.11/site-packages/serial/serialposix.py", line 325, in open
    raise SerialException(msg.errno, "could not open port {}: {}".format(self._port, msg))
serial.serialutil.SerialException: [Errno 13] could not open port /dev/ttyUSB0: [Errno 13] Permission denied: '/dev/ttyUSB0'
